<?xml version="1.0" ?>
<!-- =================================================================================== -->
<!-- |    This document was autogenerated by xacro from /home/usama/partab_6dof_ws/src/robot_urdf/urdf/arctos_urdf.xacro | -->
<!-- |    EDITING THIS FILE BY HAND IS NOT RECOMMENDED                                 | -->
<!-- =================================================================================== -->
<robot name="robot">
    <gazebo reference="base_link">
        <material>Gazebo/Blue</material>
        <color rgba="0 0 1 1" />
        <plugin name="gazebo_ros_control">
            <robotNamespace>/</robotNamespace>
        </plugin>
    </gazebo>
    <gazebo reference="Link_1_1_link">
        <material>Gazebo/Red</material>
        <color rgba="1 0 0 1" />
    </gazebo>
    <gazebo reference="Link_2_1_link">
        <material>Gazebo/Red</material>
        <color rgba="1 0 0 1" />
    </gazebo>
    <gazebo reference="Link_3_1_link">
        <material>Gazebo/Red</material>
        <color rgba="1 0 0 1" />
    </gazebo>
    <gazebo reference="Link_4_1_link">
        <material>Gazebo/Red</material>
        <color rgba="1 0 0 1" />
    </gazebo>
    <gazebo reference="Link_5_1_link">
        <material>Gazebo/Red</material>
        <color rgba="1 0 0 1" />
    </gazebo>
    <gazebo reference="Link_6_1_link">
        <material>Gazebo/Purple</material>
        <color rgba="1 0 1 1" />
    </gazebo>
    <gazebo reference="Gripper_link">
        <material>Gazebo/Red</material>
        <color rgba="1 0 0 1" />
    </gazebo>
    <gazebo reference="left_jaw_link">
        <material>Gazebo/Black</material>
        <color rgba="0 0 0 1" />
    </gazebo>
    <gazebo reference="right_jaw_link">
        <material>Gazebo/Black</material>
        <color rgba="0 0 0 1" />
    </gazebo>
    <!-- fixed frame-->
    <link name="map" />
    <!-- base_joint -->
    <joint name="base_joint" type="fixed">
        <parent link="map" />
        <child link="base_link" />
        <origin rpy="0.0 0.0 0.0" xyz="0.0 0.0 0.0" />
    </joint>
    <link name="base_link">
        <visual>
            <origin rpy="0 0.0 0" xyz="0 0 0" />
            <geometry>
                <mesh filename="package://robot_urdf/meshes/base_link.stl" scale="0.001 0.001 0.001" />
            </geometry>
        </visual>
        <collision>
            <origin rpy="0 0 0" xyz="0 0 0" />
            <geometry>
                <mesh filename="package://robot_urdf/meshes/base_link.stl" scale="0.001 0.001 0.001" />
            </geometry>
        </collision>
        <inertial>
            <origin rpy="0 0 0" xyz="0.0009375030874740357 0.047087016508753216 0.06663230338123677" />
            <mass value="7.598577592821282" />
            <inertia ixx="0.063328" ixy="-0.000434" ixz="0.000108" iyy="0.03095" iyz="0.001366" izz="0.072371" />
        </inertial>
    </link>
    <!-- Link_1_1 -->
    <joint name="joint_1" type="continuous">
        <axis xyz="0.0 0.0 1.0" />
        <parent link="base_link" />
        <child link="Link_1_1_link" />
        <origin rpy="0 0 0" xyz="0.0 0.000529 0.111" />
    </joint>
    <link name="Link_1_1_link">
        <visual>
            <origin rpy="0 0 0" xyz="-0.0 -0.000529 -0.111" />
            <geometry>
                <mesh filename="package://robot_urdf/meshes/Link_1_1.stl" scale="0.001 0.001 0.001" />
            </geometry>
        </visual>
        <collision>
            <origin rpy="0 0 0" xyz="-0.0 -0.000529 -0.111" />
            <geometry>
                <mesh filename="package://robot_urdf/meshes/Link_1_1.stl" scale="0.001 0.001 0.001" />
            </geometry>
        </collision>
        <inertial>
            <origin rpy="0 0 0" xyz="0.0022188890353287776 -0.004863444449475237 0.08546835509394825" />
            <mass value="10.394711633971145" />
            <inertia ixx="0.061139" ixy="0.00017" ixz="-0.00148" iyy="0.073854" iyz="0.003835" izz="0.05669" />
        </inertial>
        <transmission name="transmission_1">
            <type>transmission_interface/SimpleTransmission</type>
            <joint name="joint_1">
                <hardwareInterface>hardware_interface/PositionJointInterface</hardwareInterface>
            </joint>
            <actuator name="motor_1">
                <hardwareInterface>hardware_interface/PositionJointInterface</hardwareInterface>
                <mechanicalReduction>1</mechanicalReduction>
            </actuator>
        </transmission>
    </link>
    <!-- Link_2_1 -->
    <joint name="joint_2" type="revolute">
        <limit effort="10" lower="-1.68" upper="2.45" velocity="3.0" />
        <!-- 360 degree-->
        <axis xyz="1 0.0 0" />
        <parent link="Link_1_1_link" />
        <child link="Link_2_1_link" />
        <origin rpy="0 0 0" xyz="-0.05713 -0.020885 0.178378" />
    </joint>
    <link name="Link_2_1_link">
        <visual>
            <origin rpy="0 0 0" xyz="0.05713 0.020356 -0.289378" />
            <geometry>
                <mesh filename="package://robot_urdf/meshes/Link_2_1.stl" scale="0.001 0.001 0.001" />
            </geometry>
        </visual>
        <collision>
            <origin rpy="0 0 0" xyz="0.05713 0.020356 -0.289378" />
            <geometry>
                <mesh filename="package://robot_urdf/meshes/Link_2_1.stl" scale="0.001 0.001 0.001" />
            </geometry>
        </collision>
        <inertial>
            <origin rpy="0 0 0" xyz="0.055314283466519745 0.010843565259072822 0.11412354328486207" />
            <mass value="11.558090086674309" />
            <inertia ixx="0.128567" ixy="3e-06" ixz="0.001539" iyy="0.14463" iyz="-0.003293" izz="0.044463" />
        </inertial>
        <transmission name="transmission_2">
            <type>transmission_interface/SimpleTransmission</type>
            <joint name="joint_2">
                <hardwareInterface>hardware_interface/PositionJointInterface</hardwareInterface>
            </joint>
            <actuator name="motor_2">
                <hardwareInterface>hardware_interface/PositionJointInterface</hardwareInterface>
                <mechanicalReduction>1</mechanicalReduction>
            </actuator>
        </transmission>
    </link>
    <!-- Link_3_1 -->
    <joint name="joint_3" type="revolute">
        <limit effort="10" lower="-0.94" upper="1.95" velocity="3.0" />
        <!-- 360 degree-->
        <axis xyz="-1 0.0 0" />
        <parent link="Link_2_1_link" />
        <child link="Link_3_1_link" />
        <origin rpy="0 0 0" xyz="0.10013 0.001311 0.261007" />
    </joint>
    <link name="Link_3_1_link">
        <visual>
            <origin rpy="0 0 0" xyz="-0.043 0.019045 -0.550385" />
            <geometry>
                <mesh filename="package://robot_urdf/meshes/Link_3_1.stl" scale="0.001 0.001 0.001" />
            </geometry>
        </visual>
        <collision>
            <origin rpy="0 0 0" xyz="-0.043 0.019045 -0.550385" />
            <geometry>
                <mesh filename="package://robot_urdf/meshes/Link_3_1.stl" scale="0.001 0.001 0.001" />
            </geometry>
        </collision>
        <inertial>
            <origin rpy="0 0 0" xyz="-0.04178369242643258 -0.03913025368943244 0.01221763827191602" />
            <mass value="3.601405589552794" />
            <inertia ixx="0.012497" ixy="-3.6e-05" ixz="-8.1e-05" iyy="0.006916" iyz="0.001536" izz="0.011789" />
        </inertial>
        <transmission name="transmission_3">
            <type>transmission_interface/SimpleTransmission</type>
            <joint name="joint_3">
                <hardwareInterface>hardware_interface/PositionJointInterface</hardwareInterface>
            </joint>
            <actuator name="motor_3">
                <hardwareInterface>hardware_interface/PositionJointInterface</hardwareInterface>
                <mechanicalReduction>1</mechanicalReduction>
            </actuator>
        </transmission>
    </link>
    <!-- Link_4_1 -->
    <joint name="joint_4" type="revolute">
        <limit effort="10" lower="-1.5708" upper="1.5708" velocity="3.0" />
        <!-- 360 degree-->
        <axis xyz="0 1 0" />
        <parent link="Link_3_1_link" />
        <child link="Link_4_1_link" />
        <origin rpy="0 0 0" xyz="-0.042999 -0.139695 0.021705" />
    </joint>
    <link name="Link_4_1_link">
        <visual>
            <origin rpy="0 0 0" xyz="-1e-06 0.15874 -0.57209" />
            <geometry>
                <mesh filename="package://robot_urdf/meshes/Link_4_1.stl" scale="0.001 0.001 0.001" />
            </geometry>
        </visual>
        <collision>
            <origin rpy="0 0 0" xyz="-1e-06 0.15874 -0.57209" />
            <geometry>
                <mesh filename="package://robot_urdf/meshes/Link_4_1.stl" scale="0.001 0.001 0.001" />
            </geometry>
        </collision>
        <inertial>
            <origin rpy="0 0 0" xyz="0.00021104999825562586 -0.06028834880207104 -0.0005408226217131773" />
            <mass value="3.7852887653107565" />
            <inertia ixx="0.011624" ixy="-9e-06" ixz="4e-06" iyy="0.011491" iyz="-7.1e-05" izz="0.017363" />
        </inertial>
        <transmission name="transmission_4">
            <type>transmission_interface/SimpleTransmission</type>
            <joint name="joint_4">
                <hardwareInterface>hardware_interface/PositionJointInterface</hardwareInterface>
            </joint>
            <actuator name="motor_4">
                <hardwareInterface>hardware_interface/PositionJointInterface</hardwareInterface>
                <mechanicalReduction>1</mechanicalReduction>
            </actuator>
        </transmission>
    </link>
    <!-- Link_5_1 -->
    <joint name="joint_5" type="revolute">
        <limit effort="10" lower="-1.5708" upper="1.5708" velocity="3.0" />
        <!-- 360 degree-->
        <axis xyz="-1 0 0" />
        <parent link="Link_4_1_link" />
        <child link="Link_5_1_link" />
        <origin rpy="0 0 0" xyz="-0.039012 -0.121187 -0.001774" />
    </joint>
    <link name="Link_5_1_link">
        <visual>
            <origin rpy="0 0 0" xyz="0.039011 0.279927 -0.570316" />
            <geometry>
                <mesh filename="package://robot_urdf/meshes/Link_5_1.stl" scale="0.001 0.001 0.001" />
            </geometry>
        </visual>
        <collision>
            <origin rpy="0 0 0" xyz="0.039011 0.279927 -0.570316" />
            <geometry>
                <mesh filename="package://robot_urdf/meshes/Link_5_1.stl" scale="0.001 0.001 0.001" />
            </geometry>
        </collision>
        <inertial>
            <origin rpy="0 0 0" xyz="0.0397291414278933 -0.012662394123331089 0.0007929187272999183" />
            <mass value="0.8319811655030993" />
            <inertia ixx="0.000732" ixy="-1.2e-05" ixz="5e-06" iyy="0.000958" iyz="-5e-06" izz="0.000907" />
        </inertial>
        <transmission name="transmission_5">
            <type>transmission_interface/SimpleTransmission</type>
            <joint name="joint_5">
                <hardwareInterface>hardware_interface/PositionJointInterface</hardwareInterface>
            </joint>
            <actuator name="motor_5">
                <hardwareInterface>hardware_interface/PositionJointInterface</hardwareInterface>
                <mechanicalReduction>1</mechanicalReduction>
            </actuator>
        </transmission>
    </link>
    <!-- Link_6_1 (Hand rotating joint)-->
    <joint name="joint_6" type="revolute">
        <limit effort="10" lower="-1.5708" upper="1.5708" velocity="3.0" />
        <!-- 360 degree-->
        <axis xyz="0 1 0" />
        <parent link="Link_5_1_link" />
        <child link="Link_6_1_link" />
        <origin rpy="0 0 0" xyz="0.039204 -0.033835 0.0" />
    </joint>
    <link name="Link_6_1_link">
        <visual>
            <origin rpy="0 0 0" xyz="-0.000193 0.313762 -0.570316" />
            <geometry>
                <mesh filename="package://robot_urdf/meshes/Link_6_1.stl" scale="0.001 0.001 0.001" />
            </geometry>
        </visual>
        <collision>
            <origin rpy="0 0 0" xyz="-0.000193 0.313762 -0.570316" />
            <geometry>
                <mesh filename="package://robot_urdf/meshes/Link_6_1.stl" scale="0.001 0.001 0.001" />
            </geometry>
        </collision>
        <inertial>
            <origin rpy="0 0 0" xyz="6.567946382108388e-08 -0.003042398377876454 -3.032508957279134e-07" />
            <mass value="0.10343478090890781" />
            <inertia ixx="5.2e-05" ixy="-0.0" ixz="0.0" iyy="0.000103" iyz="0.0" izz="5.2e-05" />
        </inertial>
        <transmission name="transmission_6">
            <type>transmission_interface/SimpleTransmission</type>
            <joint name="joint_6">
                <hardwareInterface>hardware_interface/PositionJointInterface</hardwareInterface>
            </joint>
            <actuator name="motor_6">
                <hardwareInterface>hardware_interface/PositionJointInterface</hardwareInterface>
                <mechanicalReduction>1</mechanicalReduction>
            </actuator>
        </transmission>
    </link>
    <!-- Link_Gripper-->
    <joint name="Gripper_joint" type="fixed">
        <parent link="Link_6_1_link" />
        <child link="Gripper_link" />
        <origin rpy="0 0 0" xyz="0.0 -0.006085 0.0" />
    </joint>
    <link name="Gripper_link">
        <visual>
            <origin rpy="0 0 0" xyz="-0.000193 0.319847 -0.570316" />
            <geometry>
                <mesh filename="package://robot_urdf/meshes/Gripper.stl" scale="0.001 0.001 0.001" />
            </geometry>
        </visual>
        <collision>
            <origin rpy="0 0 0" xyz="-0.000193 0.319847 -0.570316" />
            <geometry>
                <mesh filename="package://robot_urdf/meshes/Gripper.stl" scale="0.001 0.001 0.001" />
            </geometry>
        </collision>
        <inertial>
            <origin rpy="0 0 0" xyz="0.0036112727264542635 -0.014760653808445767 -0.00103677815369696" />
            <mass value="0.5810486809925093" />
            <inertia ixx="0.000385" ixy="1e-05" ixz="3e-06" iyy="0.000495" iyz="-2e-06" izz="0.000263" />
        </inertial>
    </link>
    <!-- left_jaw -->
    <joint name="left_jaw_joint" type="prismatic">
        <limit effort="100" lower="0.0" upper="0.015" velocity="100" />
        <axis xyz="0.0 0.0 -1.0" />
        <parent link="Gripper_link" />
        <child link="left_jaw_link" />
        <origin rpy="0 0 0" xyz="0.007741 -0.039998 0.029551" />
    </joint>
    <link name="left_jaw_link">
        <visual>
            <origin rpy="0 0 0" xyz="-0.007934 0.359845 -0.599867" />
            <geometry>
                <mesh filename="package://robot_urdf/meshes/Left_jaw.stl" scale="0.001 0.001 0.001" />
            </geometry>
        </visual>
        <collision>
            <origin rpy="0 0 0" xyz="-0.007934 0.359845 -0.599867" />
            <geometry>
                <mesh filename="package://robot_urdf/meshes/Left_jaw.stl" scale="0.001 0.001 0.001" />
            </geometry>
        </collision>
        <inertial>
            <origin rpy="0 0 0" xyz="-0.011142702480351952 -0.009692440309284511 -0.009385792627785827" />
            <mass value="0.07369602565859415" />
            <inertia ixx="1.1e-05" ixy="2e-06" ixz="-0.0" iyy="6e-06" iyz="-0.0" izz="1.4e-05" />
        </inertial>
        <transmission name="left_jaw_transmission">
            <type>transmission_interface/SimpleTransmission</type>
            <joint name="left_jaw_joint">
                <hardwareInterface>hardware_interface/PositionJointInterface</hardwareInterface>
            </joint>
            <actuator name="motor_1">
                <hardwareInterface>hardware_interface/PositionJointInterface</hardwareInterface>
                <mechanicalReduction>1</mechanicalReduction>
            </actuator>
        </transmission>
    </link>
    <!-- right_jaw -->
    <joint name="right_jaw_joint" type="prismatic">
        <limit effort="100" lower="0.0" upper="0.015" velocity="100" />
        <axis xyz="0.0 0.0 1.0" />
        <parent link="Gripper_link" />
        <child link="right_jaw_link" />
        <origin rpy="0 0 0" xyz="0.007741 -0.039998 -0.030449" />
    </joint>
    <link name="right_jaw_link">
        <visual>
            <origin rpy="0 0 0" xyz="-0.007934 0.359845 -0.539867" />
            <geometry>
                <mesh filename="package://robot_urdf/meshes/Right_jaw.stl" scale="0.001 0.001 0.001" />
            </geometry>
        </visual>
        <collision>
            <origin rpy="0 0 0" xyz="-0.007934 0.359845 -0.539867" />
            <geometry>
                <mesh filename="package://robot_urdf/meshes/Right_jaw.stl" scale="0.001 0.001 0.001" />
            </geometry>
        </collision>
        <inertial>
            <origin rpy="0 0 0" xyz="-0.008289104952972526 -0.009768535307719373 0.009395511902715814" />
            <mass value="0.07312902168719511" />
            <inertia ixx="1.1e-05" ixy="-1e-06" ixz="-1e-06" iyy="6e-06" iyz="0.0" izz="1.4e-05" />
        </inertial>
        <transmission name="right_jaw_transmission">
            <type>transmission_interface/SimpleTransmission</type>
            <joint name="right_jaw_joint">
                <hardwareInterface>hardware_interface/PositionJointInterface</hardwareInterface>
            </joint>
            <actuator name="motor_1">
                <hardwareInterface>hardware_interface/PositionJointInterface</hardwareInterface>
                <mechanicalReduction>1</mechanicalReduction>
            </actuator>
        </transmission>
    </link>
    <!-- gazebo ros_control plugin -->
    <gazebo>
        <plugin filename="libgazebo_ros_control.so" name="gazebo_ros_control">
            <robotNamespace>/robot</robotNamespace>
            <robotSimType>gazebo_ros_control/DefaultRobotHWSim</robotSimType>
            <legacyModeNS>true</legacyModeNS>
        </plugin>
    </gazebo>
    <transmission name="trans_joint_1">
        <type>transmission_interface/SimpleTransmission</type>
        <joint name="joint_1">
            <hardwareInterface>hardware_interface/PositionJointInterface</hardwareInterface>
        </joint>
        <actuator name="joint_1_motor">
            <hardwareInterface>hardware_interface/PositionJointInterface</hardwareInterface>
            <mechanicalReduction>1</mechanicalReduction>
        </actuator>
    </transmission>
    <transmission name="trans_joint_2">
        <type>transmission_interface/SimpleTransmission</type>
        <joint name="joint_2">
            <hardwareInterface>hardware_interface/PositionJointInterface</hardwareInterface>
        </joint>
        <actuator name="joint_2_motor">
            <hardwareInterface>hardware_interface/PositionJointInterface</hardwareInterface>
            <mechanicalReduction>1</mechanicalReduction>
        </actuator>
    </transmission>
    <transmission name="trans_joint_3">
        <type>transmission_interface/SimpleTransmission</type>
        <joint name="joint_3">
            <hardwareInterface>hardware_interface/PositionJointInterface</hardwareInterface>
        </joint>
        <actuator name="joint_3_motor">
            <hardwareInterface>hardware_interface/PositionJointInterface</hardwareInterface>
            <mechanicalReduction>1</mechanicalReduction>
        </actuator>
    </transmission>
    <transmission name="trans_joint_4">
        <type>transmission_interface/SimpleTransmission</type>
        <joint name="joint_4">
            <hardwareInterface>hardware_interface/PositionJointInterface</hardwareInterface>
        </joint>
        <actuator name="joint_4_motor">
            <hardwareInterface>hardware_interface/PositionJointInterface</hardwareInterface>
            <mechanicalReduction>1</mechanicalReduction>
        </actuator>
    </transmission>
    <transmission name="trans_joint_5">
        <type>transmission_interface/SimpleTransmission</type>
        <joint name="joint_5">
            <hardwareInterface>hardware_interface/PositionJointInterface</hardwareInterface>
        </joint>
        <actuator name="joint_5_motor">
            <hardwareInterface>hardware_interface/PositionJointInterface</hardwareInterface>
            <mechanicalReduction>1</mechanicalReduction>
        </actuator>
    </transmission>
    <transmission name="trans_joint_6">
        <type>transmission_interface/SimpleTransmission</type>
        <joint name="joint_6">
            <hardwareInterface>hardware_interface/PositionJointInterface</hardwareInterface>
        </joint>
        <actuator name="joint_6_motor">
            <hardwareInterface>hardware_interface/PositionJointInterface</hardwareInterface>
            <mechanicalReduction>1</mechanicalReduction>
        </actuator>
    </transmission>
    <transmission name="trans_left_jaw_joint">
        <type>transmission_interface/SimpleTransmission</type>
        <joint name="left_jaw_joint">
            <hardwareInterface>hardware_interface/PositionJointInterface</hardwareInterface>
        </joint>
        <actuator name="left_jaw_joint_motor">
            <hardwareInterface>hardware_interface/PositionJointInterface</hardwareInterface>
            <mechanicalReduction>1</mechanicalReduction>
        </actuator>
    </transmission>
    <transmission name="trans_right_jaw_joint">
        <type>transmission_interface/SimpleTransmission</type>
        <joint name="right_jaw_joint">
            <hardwareInterface>hardware_interface/PositionJointInterface</hardwareInterface>
        </joint>
        <actuator name="right_jaw_joint_motor">
            <hardwareInterface>hardware_interface/PositionJointInterface</hardwareInterface>
            <mechanicalReduction>1</mechanicalReduction>
        </actuator>
    </transmission>
</robot>

